Workbook

Sheet Inputs
A1: variable_id | B1: key | C1: concept | D1: description | E1: unit | F1: downside | G1: base | H1: upside | I1: fact_or_assumption | J1: source_ids | K1: limitation
A2: CLA-V01 | B2: fx | C2: ALL | D2: Exchange rate used to convert USD API prices | E2: JPY per USD | F2: 155 | G2: 155 | H2: 155 | I2: ASSUMPTION | J2: CLA-S090 | K2: Search-reported 2026 average ~158; not an official rate
A3: CLA-V02 | B3: cpi | C3: ALL | D3: Paid cost per app install | E3: JPY/install | F3: 600 | G3: 450 | H3: 300 | I3: ASSUMPTION anchored on third-party benchmarks | J3: CLA-S070;CLA-S071 | K3: Benchmarks are dated (2019 shopping CPI USD 3.59; JP iOS USD 2.63 / Android 1.67) and not category-specific for utilities
A4: CLA-V03 | B4: p_signup | C4: ALL | D4: Install -> account created | E4: share | F4: 0.6 | G4: 0.7 | H4: 0.8 | I4: ASSUMPTION | K4: No JP benchmark found
A5: CLA-V04 | B5: p_perm | C5: ALL | D5: Account -> grants inbox access or sets up forwarding | E5: share | F5: 0.25 | G5: 0.4 | H5: 0.55 | I5: ASSUMPTION | J5: CLA-S060 | K5: No permission-conversion benchmark found; Visa JP survey shows distrust of delegation but did not measure inbox connection
A6: CLA-V05 | B6: p_ingest | C6: ALL | D6: Permission -> at least one order correctly ingested within 7 days | E6: share | F6: 0.6 | G6: 0.75 | H6: 0.85 | I6: ASSUMPTION | J6: CLA-S040;CLA-S041 | K6: Amazon removed item names from confirmation emails (2026-07-08, documented for US; JP applicability unverified)
A7: CLA-V06 | B7: p_ret3 | C7: ALL | D7: Activated user still active in month 3 | E7: share of activated | F7: 0.1 | G7: 0.2 | H7: 0.35 | I7: ASSUMPTION | J7: CLA-S072 | K7: Shopping-app benchmark is D30 ~4% of installs in APAC (Adjust); a passive tracker may differ
A8: CLA-V07 | B8: churn | C8: ALL | D8: Monthly churn of users active after month 3 | E8: share/month | F8: 0.12 | G8: 0.08 | H8: 0.05 | I8: ASSUMPTION | K8: No source
A9: CLA-V08 | B9: horizon | C9: ALL | D9: Maximum lifetime counted (no perpetual LTV) | E9: months | F9: 36 | G9: 36 | H9: 36 | I9: ASSUMPTION | K9: Cap chosen to avoid perpetual LTV
A10: CLA-V09 | B10: orders | C10: ALL | D10: Physical-goods online orders per active user | E10: orders/month | F10: 3 | G10: 4 | H10: 6 | I10: ASSUMPTION | J10: CLA-S020 | K10: MIC: JPY 47,300/month per net-shopping household (2025, 2+ person households, includes services); order count not published in sources found
A11: CLA-V10 | B11: emails_per_order | C11: C01 | D11: Commerce emails per order (confirm, ship, deliver) | E11: emails/order | F11: 3 | G11: 3 | H11: 3 | I11: ASSUMPTION | K11: Varies by merchant
A12: CLA-V11 | B12: tok_in_email | C12: C01 | D12: Input tokens per parsed email after HTML stripping | E12: tokens | F12: 3500 | G12: 3000 | H12: 2500 | I12: ASSUMPTION | K12: Not measured
A13: CLA-V12 | B13: tok_out_email | C13: C01 | D13: Output tokens per parsed email (structured JSON) | E13: tokens | F13: 400 | G13: 300 | H13: 250 | I13: ASSUMPTION | K13: Not measured
A14: CLA-V13 | B14: small_in | C14: C01 | D14: Small-model input price (Claude Haiku 4.5) | E14: USD per M tokens | F14: 1 | G14: 1 | H14: 1 | I14: FACT | J14: CLA-S091 | K14: List price cached 2026-09-25; any comparable small model would do
A15: CLA-V14 | B15: small_out | C15: C01 | D15: Small-model output price (Claude Haiku 4.5) | E15: USD per M tokens | F15: 5 | G15: 5 | H15: 5 | I15: FACT | J15: CLA-S091 | K15: List price cached 2026-09-25
A16: CLA-V15 | B16: overhead | C16: ALL | D16: Retry / failed-parse / re-validation multiplier on inference | E16: multiplier | F16: 1.2 | G16: 1.15 | H16: 1.1 | I16: ASSUMPTION | K16: Not measured
A17: CLA-V16 | B17: notif_per_order | C17: C01 | D17: User notifications per order | E17: messages/order | F17: 2 | G17: 2 | H17: 2 | I17: ASSUMPTION
A18: CLA-V17 | B18: line_share | C18: C01 | D18: Share of notifications sent as paid LINE messages (rest via free push) | E18: share | F18: 0.5 | G18: 0.25 | H18: 0 | I18: ASSUMPTION | J18: CLA-S050
A19: CLA-V18 | B19: line_cost | C19: C01 | D19: LINE official account additional message price (<=200k/month) | E19: JPY/message | F19: 3 | G19: 3 | H19: 3 | I19: FACT | J19: CLA-S050 | K19: Effective 2026-10-01 per LY Corp notice (search-reported); plan fees ignored
A20: CLA-V19 | B20: hosting | C20: ALL | D20: Variable hosting/storage/monitoring | E20: JPY/active/month | F20: 12 | G20: 6 | H20: 3 | I20: ASSUMPTION | K20: Not measured
A21: CLA-V20 | B21: support_rate | C21: ALL | D21: Support contacts | E21: contacts/active/month | F21: 0.05 | G21: 0.03 | H21: 0.015 | I21: ASSUMPTION
A22: CLA-V21 | B22: support_min | C22: ALL | D22: Minutes per support contact | E22: minutes | F22: 12 | G22: 8 | H22: 6 | I22: ASSUMPTION
A23: CLA-V22 | B23: labor_min | C23: ALL | D23: Fully loaded human cost (paid or replacement cost of founder time) | E23: JPY/minute | F23: 50 | G23: 50 | H23: 50 | I23: ASSUMPTION derived from wage postings | J23: CLA-S073 | K23: Tokyo CS postings JPY 1,650-1,750/hour x ~1.75 load factor ~= JPY 3,000/hour
A24: CLA-V23 | B24: exc_rate | C24: ALL | D24: Ingestion/handoff exceptions needing human review | E24: exceptions/active/month | F24: 0.1 | G24: 0.05 | H24: 0.02 | I24: ASSUMPTION | K24: Includes mis-matched packages, wrong item, disputed attribution
A25: CLA-V24 | B25: exc_min | C25: ALL | D25: Minutes per exception | E25: minutes | F25: 5 | G25: 4 | H25: 3 | I25: ASSUMPTION
A26: CLA-V25 | B26: coverage | C26: C03 | D26: Share of user's orders at merchants with a usable affiliate/handoff path | E26: share | F26: 0.6 | G26: 0.75 | H26: 0.85 | I26: ASSUMPTION | J26: CLA-S030;CLA-S031;CLA-S033 | K26: Amazon/Rakuten/Yahoo have affiliate programs; some retailers have none; Amazon Creators API gated by 10 sales/30 days
A27: CLA-V26 | B27: handoff | C27: C03 | D27: Share of eligible orders started through the agent | E27: share | F27: 0.05 | G27: 0.15 | H27: 0.3 | I27: ASSUMPTION | J27: CLA-S060 | K27: No observed data; Visa JP survey: 27% would not delegate even if accuracy concerns resolved
A28: CLA-V27 | B28: completion | C28: C03 | D28: Handoff -> user completes purchase on merchant site | E28: share | F28: 0.5 | G28: 0.65 | H28: 0.8 | I28: ASSUMPTION
A29: CLA-V28 | B29: attributable | C29: C03 | D29: Completed purchase -> commission credited (cookie survives, no point-site override, eligible category, not cancelled pre-ship) | E29: share | F29: 0.5 | G29: 0.7 | H29: 0.85 | I29: ASSUMPTION | J29: CLA-S032;CLA-S034 | K29: Last-click attribution; point sites and rebates can overwrite (Honey precedent)
A30: CLA-V29 | B30: aov | C30: C03 | D30: Average order value of agent-referred orders | E30: JPY/order | F30: 4000 | G30: 5000 | H30: 6000 | I30: ASSUMPTION | K30: No verified JP AOV for this behaviour
A31: CLA-V30 | B31: comm | C31: C03 | D31: Blended gross commission rate | E31: share of order value | F31: 0.02 | G31: 0.03 | H31: 0.04 | I31: FACT-RANGE (search-reported) | J31: CLA-S030;CLA-S031 | K31: Rakuten 2-4% by genre; Amazon JP category rates ~2-8% (cap removed 2024-08-07); exact current tables not opened
A32: CLA-V31 | B32: clawback | C32: C03 | D32: Cancellations/returns reversing commission | E32: share | F32: 0.1 | G32: 0.07 | H32: 0.05 | I32: ASSUMPTION
A33: CLA-V32 | B33: passthrough | C33: C03 | D33: Share of commission returned to the user to compete with point sites/rebates | E33: share | F33: 0.4 | G33: 0.25 | H33: 0.1 | I33: ASSUMPTION | J33: CLA-S035 | K33: Rakuten Rebates (10M registered, 1,000+ stores) sets the user's reference point
A34: CLA-V33 | B34: sessions | C34: C03 | D34: Shopping-assistance sessions | E34: sessions/active/month | F34: 2 | G34: 3 | H34: 4 | I34: ASSUMPTION
A35: CLA-V34 | B35: tok_in_sess | C35: C03 | D35: Input tokens per session (catalog results + history) | E35: tokens | F35: 20000 | G35: 15000 | H35: 12000 | I35: ASSUMPTION | K35: Not measured
A36: CLA-V35 | B36: tok_out_sess | C36: C03 | D36: Output tokens per session | E36: tokens | F36: 2000 | G36: 1500 | H36: 1200 | I36: ASSUMPTION | K36: Not measured
A37: CLA-V36 | B37: mid_in | C37: C03 | D37: Mid-tier model input price (Claude Sonnet 5.5) | E37: USD per M tokens | F37: 2 | G37: 2 | H37: 2 | I37: FACT | J37: CLA-S091 | K37: List price cached 2026-09-25
A38: CLA-V37 | B38: mid_out | C38: C03 | D38: Mid-tier model output price (Claude Sonnet 5.5) | E38: USD per M tokens | F38: 10 | G38: 10 | H38: 10 | I38: FACT | J38: CLA-S091 | K38: List price cached 2026-09-25
A39: CLA-V38 | B39: price | C39: SUB | D39: Consumer subscription list price | E39: JPY/month | F39: 480 | G39: 480 | H39: 480 | I39: ASSUMPTION | K39: No WTP evidence
A40: CLA-V39 | B40: store_fee | C40: SUB | D40: App-store / billing fee | E40: share | F40: 0.15 | G40: 0.15 | H40: 0.15 | I40: ASSUMPTION | K40: Small-business rate assumed; alternative billing may change it
...

Sheet Calc
A1: output_id | B1: key | C1: concept | D1: description | E1: unit | F1: downside | G1: base | H1: upside | I1: formula
A2: CLA-O01 | B2: cost_per_email | C2: C01 | D2: Inference cost per parsed commerce email | E2: JPY/email | F2: =(Inputs!F12*Inputs!F14+Inputs!F13*Inputs!F15)/1000000*Inputs!F2*Inputs!F16 | G2: =(Inputs!G12*Inputs!G14+Inputs!G13*Inputs!G15)/1000000*Inputs!G2*Inputs!G16 | H2: =(Inputs!H12*Inputs!H14+Inputs!H13*Inputs!H15)/1000000*Inputs!H2*Inputs!H16 | I2: (tok_in_email*small_in+tok_out_email*small_out)/1000000*fx*overhead
A3: CLA-O02 | B3: inf_track | C3: C01 | D3: Tracking inference cost | E3: JPY/active/month | F3: =Inputs!F10*Inputs!F11*F2 | G3: =Inputs!G10*Inputs!G11*G2 | H3: =Inputs!H10*Inputs!H11*H2 | I3: orders*emails_per_order*cost_per_email
A4: CLA-O03 | B4: notif | C4: C01 | D4: Notification cost | E4: JPY/active/month | F4: =Inputs!F10*Inputs!F17*Inputs!F18*Inputs!F19 | G4: =Inputs!G10*Inputs!G17*Inputs!G18*Inputs!G19 | H4: =Inputs!H10*Inputs!H17*Inputs!H18*Inputs!H19 | I4: orders*notif_per_order*line_share*line_cost
A5: CLA-O04 | B5: support | C5: ALL | D5: Human support cost | E5: JPY/active/month | F5: =Inputs!F21*Inputs!F22*Inputs!F23 | G5: =Inputs!G21*Inputs!G22*Inputs!G23 | H5: =Inputs!H21*Inputs!H22*Inputs!H23 | I5: support_rate*support_min*labor_min
A6: CLA-O05 | B6: recovery | C6: ALL | D6: Human exception/recovery cost | E6: JPY/active/month | F6: =Inputs!F24*Inputs!F25*Inputs!F23 | G6: =Inputs!G24*Inputs!G25*Inputs!G23 | H6: =Inputs!H24*Inputs!H25*Inputs!H23 | I6: exc_rate*exc_min*labor_min
A7: CLA-O06 | B7: m1_cost | C7: C01 | D7: Tracking-only variable cost | E7: JPY/active/month | F7: =F3+F4+Inputs!F20+F5+F6 | G7: =G3+G4+Inputs!G20+G5+G6 | H7: =H3+H4+Inputs!H20+H5+H6 | I7: inf_track+notif+hosting+support+recovery
A8: CLA-O07 | B8: m1_contrib | C8: C01 | D8: Tracking-only contribution (no revenue; past orders are not attributable) | E8: JPY/active/month | F8: =-F7 | G8: =-G7 | H8: =-H7 | I8: -m1_cost
A9: CLA-O08 | B9: attr_orders | C9: C03 | D9: Successful attributable orders | E9: orders/active/month | F9: =Inputs!F10*Inputs!F26*Inputs!F27*Inputs!F28*Inputs!F29 | G9: =Inputs!G10*Inputs!G26*Inputs!G27*Inputs!G28*Inputs!G29 | H9: =Inputs!H10*Inputs!H26*Inputs!H27*Inputs!H28*Inputs!H29 | I9: orders*coverage*handoff*completion*attributable
A10: CLA-O09 | B10: net_rev_order | C10: C03 | D10: Net realised revenue per attributable order (after clawback and pass-through, each applied once) | E10: JPY/order | F10: =Inputs!F30*Inputs!F31*(1-Inputs!F32)*(1-Inputs!F33) | G10: =Inputs!G30*Inputs!G31*(1-Inputs!G32)*(1-Inputs!G33) | H10: =Inputs!H30*Inputs!H31*(1-Inputs!H32)*(1-Inputs!H33) | I10: aov*comm*(1-clawback)*(1-passthrough)
A11: CLA-O10 | B11: m2_rev | C11: C03 | D11: Affiliate revenue | E11: JPY/active/month | F11: =F9*F10 | G11: =G9*G10 | H11: =H9*H10 | I11: attr_orders*net_rev_order
A12: CLA-O11 | B12: cost_per_session | C12: C03 | D12: Inference cost per shopping session | E12: JPY/session | F12: =(Inputs!F35*Inputs!F37+Inputs!F36*Inputs!F38)/1000000*Inputs!F2*Inputs!F16 | G12: =(Inputs!G35*Inputs!G37+Inputs!G36*Inputs!G38)/1000000*Inputs!G2*Inputs!G16 | H12: =(Inputs!H35*Inputs!H37+Inputs!H36*Inputs!H38)/1000000*Inputs!H2*Inputs!H16 | I12: (tok_in_sess*mid_in+tok_out_sess*mid_out)/1000000*fx*overhead
A13: CLA-O12 | B13: inf_shop | C13: C03 | D13: Shopping-session inference cost | E13: JPY/active/month | F13: =Inputs!F34*F12 | G13: =Inputs!G34*G12 | H13: =Inputs!H34*H12 | I13: sessions*cost_per_session
A14: CLA-O13 | B14: m2_cost | C14: C03 | D14: Affiliate-handoff assistant variable cost | E14: JPY/active/month | F14: =F13+Inputs!F20+F5+F6 | G14: =G13+Inputs!G20+G5+G6 | H14: =H13+Inputs!H20+H5+H6 | I14: inf_shop+hosting+support+recovery
A15: CLA-O14 | B15: m2_contrib | C15: C03 | D15: Affiliate-handoff assistant contribution | E15: JPY/active/month | F15: =F11-F14 | G15: =G11-G14 | H15: =H11-H14 | I15: m2_rev-m2_cost
A16: CLA-O15 | B16: combo_contrib | C16: C01+C03 | D16: Tracking + handoff combined contribution (shared hosting/support counted once) | E16: JPY/active/month | F16: =F11-(F7+F13) | G16: =G11-(G7+G13) | H16: =H11-(H7+H13) | I16: m2_rev-(m1_cost+inf_shop)
A17: CLA-O16 | B17: net_price | C17: SUB | D17: Net subscription revenue per payer | E17: JPY/payer/month | F17: =Inputs!F39*(1-Inputs!F40) | G17: =Inputs!G39*(1-Inputs!G40) | H17: =Inputs!H39*(1-Inputs!H40) | I17: price*(1-store_fee)
A18: CLA-O17 | B18: paid_exc_cost | C18: SUB | D18: Human exception handling cost per payer | E18: JPY/payer/month | F18: =Inputs!F42*Inputs!F43*Inputs!F23 | G18: =Inputs!G42*Inputs!G43*Inputs!G23 | H18: =Inputs!H42*Inputs!H43*Inputs!H23 | I18: paid_exc_rate*paid_exc_min*labor_min
A19: CLA-O18 | B19: m3_contrib | C19: SUB | D19: Freemium subscription contribution (all actives incur tracking cost) | E19: JPY/active/month | F19: =Inputs!F41*(F17-F18)-F7 | G19: =Inputs!G41*(G17-G18)-G7 | H19: =Inputs!H41*(H17-H18)-H7 | I19: paid_conv*(net_price-paid_exc_cost)-m1_cost
A20: CLA-O19 | B20: m4_cost | C20: C07 | D20: B2B2C variable cost (no notification cost; partner absorbs part of support) | E20: JPY/MAU/month | F20: =F3+Inputs!F20+F5*(1-Inputs!F45)+F6 | G20: =G3+Inputs!G20+G5*(1-Inputs!G45)+G6 | H20: =H3+Inputs!H20+H5*(1-Inputs!H45)+H6 | I20: inf_track+hosting+support*(1-partner_support_share)+recovery
A21: CLA-O20 | B21: m4_contrib | C21: C07 | D21: B2B2C contribution | E21: JPY/MAU/month | F21: =Inputs!F44-F20 | G21: =Inputs!G44-G20 | H21: =Inputs!H44-H20 | I21: b2b2c_fee-m4_cost
A22: CLA-O21 | B22: act_rate | C22: ALL | D22: Activated users per install | E22: share | F22: =Inputs!F4*Inputs!F5*Inputs!F6 | G22: =Inputs!G4*Inputs!G5*Inputs!G6 | H22: =Inputs!H4*Inputs!H5*Inputs!H6 | I22: p_signup*p_perm*p_ingest
A23: CLA-O22 | B23: cac_act | C23: ALL | D23: Paid acquisition cost per activated user | E23: JPY/activated user | F23: =Inputs!F3/F22 | G23: =Inputs!G3/G22 | H23: =Inputs!H3/H22 | I23: cpi/act_rate
A24: CLA-O23 | B24: cac_ret | C24: ALL | D24: Paid acquisition cost per user still active in month 3 | E24: JPY/retained user | F24: =F23/Inputs!F7 | G24: =G23/Inputs!G7 | H24: =H23/Inputs!H7 | I24: cac_act/p_ret3
A25: CLA-O24 | B25: tail_months | C25: ALL | D25: Expected active months from month 3 for a retained user (capped) | E25: months | F25: =(1-(1-Inputs!F8)^(Inputs!F9-2))/Inputs!F8 | G25: =(1-(1-Inputs!G8)^(Inputs!G9-2))/Inputs!G8 | H25: =(1-(1-Inputs!H8)^(Inputs!H9-2))/Inputs!H8 | I25: (1-(1-churn)^(horizon-2))/churn
A26: CLA-O25 | B26: act_months | C26: ALL | D26: Expected active months per activated user (m1=1, m2 interpolated, m3+ retained tail) | E26: months | F26: =1+(1+Inputs!F7)/2+Inputs!F7*F25 | G26: =1+(1+Inputs!G7)/2+Inputs!G7*G25 | H26: =1+(1+Inputs!H7)/2+Inputs!H7*H25 | I26: 1+(1+p_ret3)/2+p_ret3*tail_months
A27: CLA-O26 | B27: val_act_m2 | C27: C03 | D27: Contribution per activated user over lifetime (affiliate) | E27: JPY/activated user | F27: =F15*F26 | G27: =G15*G26 | H27: =H15*H26 | I27: m2_contrib*act_months
A28: CLA-O27 | B28: val_act_m3 | C28: SUB | D28: Contribution per activated user over lifetime (subscription) | E28: JPY/activated user | F28: =F19*F26 | G28: =G19*G26 | H28: =H19*H26 | I28: m3_contrib*act_months
A29: CLA-O28 | B29: val_act_combo | C29: C01+C03 | D29: Contribution per activated user over lifetime (tracking+handoff) | E29: JPY/activated user | F29: =F16*F26 | G29: =G16*G26 | H29: =H16*H26 | I29: combo_contrib*act_months
A30: CLA-O29 | B30: max_cpi_m2 | C30: C03 | D30: Maximum sustainable paid cost per install (affiliate), floor 0 | E30: JPY/install | F30: =MAX(0,F27*F22) | G30: =MAX(0,G27*G22) | H30: =MAX(0,H27*H22) | I30: MAX(0,val_act_m2*act_rate)
A31: CLA-O30 | B31: max_cpi_m3 | C31: SUB | D31: Maximum sustainable paid cost per install (subscription), floor 0 | E31: JPY/install | F31: =MAX(0,F28*F22) | G31: =MAX(0,G28*G22) | H31: =MAX(0,H28*H22) | I31: MAX(0,val_act_m3*act_rate)
A32: CLA-O31 | B32: max_cpi_combo | C32: C01+C03 | D32: Maximum sustainable paid cost per install (tracking+handoff), floor 0 | E32: JPY/install | F32: =MAX(0,F29*F22) | G32: =MAX(0,G29*G22) | H32: =MAX(0,H29*H22) | I32: MAX(0,val_act_combo*act_rate)
A33: CLA-F01 | B33: f_min_handoff | C33: C03 | D33: FRONTIER: minimum handoff share for affiliate contribution >= 0 | E33: share | F33: =F14/(Inputs!F10*Inputs!F26*Inputs!F28*Inputs!F29*F10) | G33: =G14/(Inputs!G10*Inputs!G26*Inputs!G28*Inputs!G29*G10) | H33: =H14/(Inputs!H10*Inputs!H26*Inputs!H28*Inputs!H29*H10) | I33: m2_cost/(orders*coverage*completion*attributable*net_rev_order)
A34: CLA-F02 | B34: f_min_attr_orders | C34: C03 | D34: FRONTIER: minimum attributable orders per active for affiliate contribution >= 0 | E34: orders/active/month | F34: =F14/F10 | G34: =G14/G10 | H34: =H14/H10 | I34: m2_cost/net_rev_order
A35: CLA-F03 | B35: f_min_coverage | C35: C03 | D35: FRONTIER: minimum eligible merchant coverage for affiliate contribution >= 0 (>1 = impossible) | E35: share | F35: =F14/(Inputs!F10*Inputs!F27*Inputs!F28*Inputs!F29*F10) | G35: =G14/(Inputs!G10*Inputs!G27*Inputs!G28*Inputs!G29*G10) | H35: =H14/(Inputs!H10*Inputs!H27*Inputs!H28*Inputs!H29*H10) | I35: m2_cost/(orders*handoff*completion*attributable*net_rev_order)
A36: CLA-F04 | B36: f_max_human_min | C36: C03 | D36: FRONTIER: maximum human minutes per active per month before affiliate contribution < 0 (negative = none affordable) | E36: minutes/active/month | F36: =(F11-F13-Inputs!F20)/Inputs!F23 | G36: =(G11-G13-Inputs!G20)/Inputs!G23 | H36: =(H11-H13-Inputs!H20)/Inputs!H23 | I36: (m2_rev-inf_shop-hosting)/labor_min
A37: CLA-F05 | B37: f_max_human_min_per_order | C37: C03 | D37: FRONTIER: maximum human minutes per attributable order | E37: minutes/order | F37: =(F11-F13-Inputs!F20)/Inputs!F23/F9 | G37: =(G11-G13-Inputs!G20)/Inputs!G23/G9 | H37: =(H11-H13-Inputs!H20)/Inputs!H23/H9 | I37: (m2_rev-inf_shop-hosting)/labor_min/attr_orders
A38: CLA-F06 | B38: f_min_handoff_cac | C38: C03 | D38: FRONTIER: minimum handoff share to recover paid CAC within the capped lifetime | E38: share | F38: =(F23/F26+F14)/(Inputs!F10*Inputs!F26*Inputs!F28*Inputs!F29*F10) | G38: =(G23/G26+G14)/(Inputs!G10*Inputs!G26*Inputs!G28*Inputs!G29*G10) | H38: =(H23/H26+H14)/(Inputs!H10*Inputs!H26*Inputs!H28*Inputs!H29*H10) | I38: (cac_act/act_months+m2_cost)/(orders*coverage*completion*attributable*net_rev_order)
A39: CLA-F07 | B39: f_min_paid_conv | C39: SUB | D39: FRONTIER: minimum paid conversion for subscription contribution >= 0 | E39: share of actives | F39: =F7/(F17-F18) | G39: =G7/(G17-G18) | H39: =H7/(H17-H18) | I39: m1_cost/(net_price-paid_exc_cost)
A40: CLA-F08 | B40: f_min_paid_conv_cac | C40: SUB | D40: FRONTIER: minimum paid conversion to recover paid CAC within the capped lifetime | E40: share of actives | F40: =(F23/F26+F7)/(F17-F18) | G40: =(G23/G26+G7)/(G17-G18) | H40: =(H23/H26+H7)/(H17-H18) | I40: (cac_act/act_months+m1_cost)/(net_price-paid_exc_cost)
...
